/*
 * Licensed to the Apache Software Foundation (ASF) under one
 * or more contributor license agreements.  See the NOTICE file
 * distributed with this work for additional information
 * regarding copyright ownership.  The ASF licenses this file
 * to you under the Apache License, Version 2.0 (the
 * "License"); you may not use this file except in compliance
 * with the License.  You may obtain a copy of the License at
 *
 *     http://www.apache.org/licenses/LICENSE-2.0
 *
 * Unless required by applicable law or agreed to in writing, software
 * distributed under the License is distributed on an "AS IS" BASIS,
 * WITHOUT WARRANTIES OR CONDITIONS OF ANY KIND, either express or implied.
 * See the License for the specific language governing permissions and
 * limitations under the License.
 */

package org.apache.flink.runtime.concurrent;

import org.apache.flink.api.common.time.Time;
import org.apache.flink.core.testutils.OneShotLatch;
import org.apache.flink.runtime.messages.Acknowledge;
import org.apache.flink.runtime.testingUtils.TestingUtils;
import org.apache.flink.util.ExceptionUtils;
import org.apache.flink.util.FlinkException;
import org.apache.flink.util.TestLogger;

import org.junit.Assert;
import org.junit.Test;

import java.time.Duration;
import java.util.Arrays;
import java.util.Collection;
import java.util.List;
import java.util.concurrent.CompletableFuture;
import java.util.concurrent.CompletionException;
import java.util.concurrent.ExecutionException;
import java.util.concurrent.Executor;
import java.util.concurrent.Executors;
import java.util.concurrent.ScheduledExecutorService;
import java.util.concurrent.ScheduledFuture;
import java.util.concurrent.TimeUnit;
import java.util.concurrent.TimeoutException;
import java.util.concurrent.atomic.AtomicBoolean;
import java.util.concurrent.atomic.AtomicInteger;
import java.util.concurrent.atomic.AtomicReference;
import java.util.function.BiFunction;
import java.util.function.Supplier;

import static org.hamcrest.CoreMatchers.containsString;
import static org.hamcrest.CoreMatchers.equalTo;
import static org.hamcrest.Matchers.arrayContaining;
import static org.hamcrest.Matchers.arrayWithSize;
import static org.hamcrest.Matchers.emptyArray;
import static org.hamcrest.Matchers.is;
import static org.hamcrest.Matchers.not;
import static org.junit.Assert.assertEquals;
import static org.junit.Assert.assertFalse;
import static org.junit.Assert.assertNull;
import static org.junit.Assert.assertThat;
import static org.junit.Assert.assertTrue;
import static org.junit.Assert.fail;

/**
 * Tests for the utility methods in {@link FutureUtils}.
 */
public class FutureUtilsTest extends TestLogger {

	/**
	 * Tests that we can retry an operation.
	 */
	@Test
	public void testRetrySuccess() throws Exception {
		final int retries = 10;
		final AtomicInteger atomicInteger = new AtomicInteger(0);
		CompletableFuture<Boolean> retryFuture = FutureUtils.retry(
			() ->
				CompletableFuture.supplyAsync(
					() -> {
						if (atomicInteger.incrementAndGet() == retries) {
							return true;
						} else {
							throw new CompletionException(new FlinkException("Test exception"));
						}
					},
					TestingUtils.defaultExecutor()),
			retries,
			TestingUtils.defaultExecutor());

		assertTrue(retryFuture.get());
		assertEquals(retries, atomicInteger.get());
	}

	/**
	 * Tests that a retry future is failed after all retries have been consumed.
	 */
	@Test(expected = FutureUtils.RetryException.class)
	public void testRetryFailureFixedRetries() throws Throwable {
		final int retries = 3;

		CompletableFuture<?> retryFuture = FutureUtils.retry(
			() -> FutureUtils.completedExceptionally(new FlinkException("Test exception")),
			retries,
			TestingUtils.defaultExecutor());

		try {
			retryFuture.get();
		} catch (ExecutionException ee) {
			throw ExceptionUtils.stripExecutionException(ee);
		}
	}

	/**
	 * Tests that we can cancel a retry future.
	 */
	@Test
	public void testRetryCancellation() throws Exception {
		final int retries = 10;
		final AtomicInteger atomicInteger = new AtomicInteger(0);
		final OneShotLatch notificationLatch = new OneShotLatch();
		final OneShotLatch waitLatch = new OneShotLatch();
		final AtomicReference<Throwable> atomicThrowable = new AtomicReference<>(null);

		CompletableFuture<?> retryFuture = FutureUtils.retry(
			() ->
				CompletableFuture.supplyAsync(
					() -> {
						if (atomicInteger.incrementAndGet() == 2) {
							notificationLatch.trigger();
							try {
								waitLatch.await();
							} catch (InterruptedException e) {
								atomicThrowable.compareAndSet(null, e);
							}
						}

						throw new CompletionException(new FlinkException("Test exception"));
					},
					TestingUtils.defaultExecutor()),
			retries,
			TestingUtils.defaultExecutor());

		// await that we have failed once
		notificationLatch.await();

		assertFalse(retryFuture.isDone());

		// cancel the retry future
		retryFuture.cancel(false);

		// let the retry operation continue
		waitLatch.trigger();

		assertTrue(retryFuture.isCancelled());
		assertEquals(2, atomicInteger.get());

		if (atomicThrowable.get() != null) {
			throw new FlinkException("Exception occurred in the retry operation.", atomicThrowable.get());
		}
	}

	/**
	 * Tests that retry with delay fails after having exceeded all retries.
	 */
	@Test(expected = FutureUtils.RetryException.class)
	public void testRetryWithDelayFixedArgsFailure() throws Throwable {
		CompletableFuture<?> retryFuture = FutureUtils.retryWithDelay(
			() -> FutureUtils.completedExceptionally(new FlinkException("Test exception")),
			3,
			Time.milliseconds(1L),
			TestingUtils.defaultScheduledExecutor());

		try {
			retryFuture.get(TestingUtils.TIMEOUT().toMilliseconds(), TimeUnit.MILLISECONDS);
		} catch (ExecutionException ee) {
			throw ExceptionUtils.stripExecutionException(ee);
		}
	}

	/**
	 * Tests that retry with delay fails after having exceeded all retries.
	 */
	@Test(expected = FutureUtils.RetryException.class)
	public void testRetryWithDelayRetryStrategyFailure() throws Throwable {
		CompletableFuture<?> retryFuture = FutureUtils.retryWithDelay(
				() -> FutureUtils.completedExceptionally(new FlinkException("Test exception")),
				new FixedRetryStrategy(3, Duration.ofMillis(1L)),
				TestingUtils.defaultScheduledExecutor());

		try {
			retryFuture.get(TestingUtils.TIMEOUT().toMilliseconds(), TimeUnit.MILLISECONDS);
		} catch (ExecutionException ee) {
			throw ExceptionUtils.stripExecutionException(ee);
		}
	}

	/**
	 * Tests that the delay is respected between subsequent retries of a retry future with retry delay.
	 */
	@Test
	public void testRetryWithDelayFixedArgs() throws Exception {
		final int retries = 4;
		final Time delay = Time.milliseconds(5L);
		final AtomicInteger countDown = new AtomicInteger(retries);

		long start = System.currentTimeMillis();

		CompletableFuture<Boolean> retryFuture = FutureUtils.retryWithDelay(
			() -> {
				if (countDown.getAndDecrement() == 0) {
					return CompletableFuture.completedFuture(true);
				} else {
					return FutureUtils.completedExceptionally(new FlinkException("Test exception."));
				}
			},
			retries,
			delay,
			TestingUtils.defaultScheduledExecutor());

		Boolean result = retryFuture.get();

		long completionTime = System.currentTimeMillis() - start;

		assertTrue(result);
		assertTrue("The completion time should be at least retries times delay between retries.", completionTime >= retries * delay.toMilliseconds());
	}

	/**
	 * Tests that the delay is respected between subsequent retries of a retry future with retry delay.
	 */
	@Test
	public void testRetryWithDelayRetryStrategy() throws Exception {
		final int retries = 4;
		final Time delay = Time.milliseconds(5L);
		final AtomicInteger countDown = new AtomicInteger(retries);

		long start = System.currentTimeMillis();

		CompletableFuture<Boolean> retryFuture = FutureUtils.retryWithDelay(
				() -> {
					if (countDown.getAndDecrement() == 0) {
						return CompletableFuture.completedFuture(true);
					} else {
						return FutureUtils.completedExceptionally(new FlinkException("Test exception."));
					}
				},
				new ExponentialBackoffRetryStrategy(retries, Duration.ofMillis(2L), Duration.ofMillis(5L)),
				TestingUtils.defaultScheduledExecutor());

		Boolean result = retryFuture.get();

		long completionTime = System.currentTimeMillis() - start;

		assertTrue(result);
		assertTrue("The completion time should be at least retries times delay between retries.", completionTime >= (2 + 4 + 5 + 5));
	}

	/**
	 * Tests that all scheduled tasks are canceled if the retry future is being cancelled.
	 */
	@Test
	public void testRetryWithDelayCancellation() {
		final ManuallyTriggeredScheduledExecutor scheduledExecutor = new ManuallyTriggeredScheduledExecutor();

		CompletableFuture<?> retryFuture = FutureUtils.retryWithDelay(
			() -> FutureUtils.completedExceptionally(new FlinkException("Test exception")),
			1,
			TestingUtils.infiniteTime(),
			scheduledExecutor);

		assertFalse(retryFuture.isDone());

		final Collection<ScheduledFuture<?>> scheduledTasks = scheduledExecutor.getScheduledTasks();

		assertFalse(scheduledTasks.isEmpty());

		final ScheduledFuture<?> scheduledFuture = scheduledTasks.iterator().next();

		assertFalse(scheduledFuture.isDone());

		retryFuture.cancel(false);

		assertTrue(retryFuture.isCancelled());
		assertTrue(scheduledFuture.isCancelled());
	}

	/**
	 * Tests that the operation could be scheduled with expected delay.
	 */
	@Test
	public void testScheduleWithDelay() throws Exception {
		final ManuallyTriggeredScheduledExecutor scheduledExecutor = new ManuallyTriggeredScheduledExecutor();

		final int expectedResult = 42;
		CompletableFuture<Integer> completableFuture = FutureUtils.scheduleWithDelay(
			() -> expectedResult,
			Time.milliseconds(0),
			scheduledExecutor);

		scheduledExecutor.triggerScheduledTasks();
		final int actualResult = completableFuture.get();

		assertEquals(expectedResult, actualResult);
	}

	/**
	 * Tests that a scheduled task is canceled if the scheduled future is being cancelled.
	 */
	@Test
	public void testScheduleWithDelayCancellation() {
		final ManuallyTriggeredScheduledExecutor scheduledExecutor = new ManuallyTriggeredScheduledExecutor();

		final Runnable noOpRunnable = () -> {};
		CompletableFuture<Void> completableFuture = FutureUtils.scheduleWithDelay(
			noOpRunnable,
			TestingUtils.infiniteTime(),
			scheduledExecutor);

		final ScheduledFuture<?> scheduledFuture = scheduledExecutor
			.getScheduledTasks()
			.iterator()
			.next();

		completableFuture.cancel(false);

		assertTrue(completableFuture.isCancelled());
		assertTrue(scheduledFuture.isCancelled());
	}

	/**
	 * Tests that the operation is never scheduled if the delay is virtually infinite.
	 */
	@Test
	public void testScheduleWithInfiniteDelayNeverSchedulesOperation() {
		final Runnable noOpRunnable = () -> {};
		final CompletableFuture<Void> completableFuture = FutureUtils.scheduleWithDelay(
			noOpRunnable,
			TestingUtils.infiniteTime(),
			TestingUtils.defaultScheduledExecutor());

		assertFalse(completableFuture.isDone());

		completableFuture.cancel(false);
	}

	/**
	 * Tests that a future is timed out after the specified timeout.
	 */
	@Test
	public void testOrTimeout() throws Exception {
		final CompletableFuture<String> future = new CompletableFuture<>();
		final long timeout = 10L;

		FutureUtils.orTimeout(future, timeout, TimeUnit.MILLISECONDS);

		try {
			future.get();
		} catch (ExecutionException e) {
			assertTrue(ExceptionUtils.stripExecutionException(e) instanceof TimeoutException);
		}
	}

	@Test
	public void testRetryWithDelayAndPredicate() throws Exception {
		final ScheduledExecutorService retryExecutor = Executors.newSingleThreadScheduledExecutor();
		final String retryableExceptionMessage = "first exception";
		class TestStringSupplier implements Supplier<CompletableFuture<String>> {
			private final AtomicInteger counter = new AtomicInteger();

			@Override
			public CompletableFuture<String> get() {
				if (counter.getAndIncrement() == 0) {
					return FutureUtils.completedExceptionally(new RuntimeException(retryableExceptionMessage));
				} else {
					return FutureUtils.completedExceptionally(new RuntimeException("should propagate"));
				}
			}
		}

		try {
			FutureUtils.retryWithDelay(
				new TestStringSupplier(),
				1,
				Time.seconds(0),
				throwable ->
					throwable instanceof RuntimeException && throwable.getMessage().contains(retryableExceptionMessage),
				new ScheduledExecutorServiceAdapter(retryExecutor)).get();
		} catch (final ExecutionException e) {
			assertThat(e.getMessage(), containsString("should propagate"));
		} finally {
			retryExecutor.shutdownNow();
		}
	}

	@Test
	public void testRunAfterwards() throws Exception {
		final CompletableFuture<Void> inputFuture = new CompletableFuture<>();
		final OneShotLatch runnableLatch = new OneShotLatch();

		final CompletableFuture<Void> runFuture = FutureUtils.runAfterwards(
			inputFuture,
			runnableLatch::trigger);

		assertThat(runnableLatch.isTriggered(), is(false));
		assertThat(runFuture.isDone(), is(false));

		inputFuture.complete(null);

		assertThat(runnableLatch.isTriggered(), is(true));
		assertThat(runFuture.isDone(), is(true));

		// check that this future is not exceptionally completed
		runFuture.get();
	}

	@Test
	public void testRunAfterwardsExceptional() throws Exception {
		final CompletableFuture<Void> inputFuture = new CompletableFuture<>();
		final OneShotLatch runnableLatch = new OneShotLatch();
		final FlinkException testException = new FlinkException("Test exception");

		final CompletableFuture<Void> runFuture = FutureUtils.runAfterwards(
			inputFuture,
			runnableLatch::trigger);

		assertThat(runnableLatch.isTriggered(), is(false));
		assertThat(runFuture.isDone(), is(false));

		inputFuture.completeExceptionally(testException);

		assertThat(runnableLatch.isTriggered(), is(true));
		assertThat(runFuture.isDone(), is(true));

		try {
			runFuture.get();
			fail("Expected an exceptional completion");
		} catch (ExecutionException ee) {
			assertThat(ExceptionUtils.stripExecutionException(ee), is(testException));
		}
	}

	@Test
	public void testComposeAfterwards() throws ExecutionException, InterruptedException {
		final CompletableFuture<Void> inputFuture = new CompletableFuture<>();
		final OneShotLatch composeLatch = new OneShotLatch();

		final CompletableFuture<Void> composeFuture = FutureUtils.composeAfterwards(
			inputFuture,
			() -> {
				composeLatch.trigger();
				return CompletableFuture.completedFuture(null);
			});

		assertThat(composeLatch.isTriggered(), is(false));
		assertThat(composeFuture.isDone(), is(false));

		inputFuture.complete(null);

		assertThat(composeLatch.isTriggered(), is(true));
		assertThat(composeFuture.isDone(), is(true));

		// check that tthis future is not exceptionally completed
		composeFuture.get();
	}

	@Test
	public void testComposeAfterwardsFirstExceptional() throws InterruptedException {
		final CompletableFuture<Void> inputFuture = new CompletableFuture<>();
		final OneShotLatch composeLatch = new OneShotLatch();
		final FlinkException testException = new FlinkException("Test exception");

		final CompletableFuture<Void> composeFuture = FutureUtils.composeAfterwards(
			inputFuture,
			() -> {
				composeLatch.trigger();
				return CompletableFuture.completedFuture(null);
			});

		assertThat(composeLatch.isTriggered(), is(false));
		assertThat(composeFuture.isDone(), is(false));

		inputFuture.completeExceptionally(testException);

		assertThat(composeLatch.isTriggered(), is(true));
		assertThat(composeFuture.isDone(), is(true));

		// check that this future is not exceptionally completed
		try {
			composeFuture.get();
			fail("Expected an exceptional completion");
		} catch (ExecutionException ee) {
			assertThat(ExceptionUtils.stripExecutionException(ee), is(testException));
		}
	}

	@Test
	public void testComposeAfterwardsSecondExceptional() throws InterruptedException {
		final CompletableFuture<Void> inputFuture = new CompletableFuture<>();
		final OneShotLatch composeLatch = new OneShotLatch();
		final FlinkException testException = new FlinkException("Test exception");

		final CompletableFuture<Void> composeFuture = FutureUtils.composeAfterwards(
			inputFuture,
			() -> {
				composeLatch.trigger();
				return FutureUtils.completedExceptionally(testException);
			});

		assertThat(composeLatch.isTriggered(), is(false));
		assertThat(composeFuture.isDone(), is(false));

		inputFuture.complete(null);

		assertThat(composeLatch.isTriggered(), is(true));
		assertThat(composeFuture.isDone(), is(true));

		// check that this future is not exceptionally completed
		try {
			composeFuture.get();
			fail("Expected an exceptional completion");
		} catch (ExecutionException ee) {
			assertThat(ExceptionUtils.stripExecutionException(ee), is(testException));
		}
	}

	@Test
	public void testComposeAfterwardsBothExceptional() throws InterruptedException {
		final CompletableFuture<Void> inputFuture = new CompletableFuture<>();
		final FlinkException testException1 = new FlinkException("Test exception1");
		final FlinkException testException2 = new FlinkException("Test exception2");
		final OneShotLatch composeLatch = new OneShotLatch();

		final CompletableFuture<Void> composeFuture = FutureUtils.composeAfterwards(
			inputFuture,
			() -> {
				composeLatch.trigger();
				return FutureUtils.completedExceptionally(testException2);
			});

		assertThat(composeLatch.isTriggered(), is(false));
		assertThat(composeFuture.isDone(), is(false));

		inputFuture.completeExceptionally(testException1);

		assertThat(composeLatch.isTriggered(), is(true));
		assertThat(composeFuture.isDone(), is(true));

		// check that this future is not exceptionally completed
		try {
			composeFuture.get();
			fail("Expected an exceptional completion");
		} catch (ExecutionException ee) {
			final Throwable actual = ExceptionUtils.stripExecutionException(ee);
			assertThat(actual, is(testException1));
			assertThat(actual.getSuppressed(), arrayWithSize(1));
			assertThat(actual.getSuppressed()[0], is(testException2));
		}
	}

	@Test
	public void testCompleteAll() throws Exception {
		final CompletableFuture<String> inputFuture1 = new CompletableFuture<>();
		final CompletableFuture<Integer> inputFuture2 = new CompletableFuture<>();

		final List<CompletableFuture<?>> futuresToComplete = Arrays.asList(inputFuture1, inputFuture2);
		final FutureUtils.ConjunctFuture<Void> completeFuture = FutureUtils.completeAll(futuresToComplete);

		assertThat(completeFuture.isDone(), is(false));
		assertThat(completeFuture.getNumFuturesCompleted(), is(0));
		assertThat(completeFuture.getNumFuturesTotal(), is(futuresToComplete.size()));

		inputFuture2.complete(42);

		assertThat(completeFuture.isDone(), is(false));
		assertThat(completeFuture.getNumFuturesCompleted(), is(1));

		inputFuture1.complete("foobar");

		assertThat(completeFuture.isDone(), is(true));
		assertThat(completeFuture.getNumFuturesCompleted(), is(2));

		completeFuture.get();
	}

	@Test
	public void testCompleteAllPartialExceptional() throws Exception {
		final CompletableFuture<String> inputFuture1 = new CompletableFuture<>();
		final CompletableFuture<Integer> inputFuture2 = new CompletableFuture<>();

		final List<CompletableFuture<?>> futuresToComplete = Arrays.asList(inputFuture1, inputFuture2);
		final FutureUtils.ConjunctFuture<Void> completeFuture = FutureUtils.completeAll(futuresToComplete);

		assertThat(completeFuture.isDone(), is(false));
		assertThat(completeFuture.getNumFuturesCompleted(), is(0));
		assertThat(completeFuture.getNumFuturesTotal(), is(futuresToComplete.size()));

		final FlinkException testException1 = new FlinkException("Test exception 1");
		inputFuture2.completeExceptionally(testException1);

		assertThat(completeFuture.isDone(), is(false));
		assertThat(completeFuture.getNumFuturesCompleted(), is(1));

		inputFuture1.complete("foobar");

		assertThat(completeFuture.isDone(), is(true));
		assertThat(completeFuture.getNumFuturesCompleted(), is(2));

		try {
			completeFuture.get();
			fail("Expected an exceptional completion");
		} catch (ExecutionException ee) {
			assertThat(ExceptionUtils.stripExecutionException(ee), is(testException1));
		}
	}

	@Test
	public void testCompleteAllExceptional() throws Exception {
		final CompletableFuture<String> inputFuture1 = new CompletableFuture<>();
		final CompletableFuture<Integer> inputFuture2 = new CompletableFuture<>();

		final List<CompletableFuture<?>> futuresToComplete = Arrays.asList(inputFuture1, inputFuture2);
		final FutureUtils.ConjunctFuture<Void> completeFuture = FutureUtils.completeAll(futuresToComplete);

		assertThat(completeFuture.isDone(), is(false));
		assertThat(completeFuture.getNumFuturesCompleted(), is(0));
		assertThat(completeFuture.getNumFuturesTotal(), is(futuresToComplete.size()));

		final FlinkException testException1 = new FlinkException("Test exception 1");
		inputFuture1.completeExceptionally(testException1);

		assertThat(completeFuture.isDone(), is(false));
		assertThat(completeFuture.getNumFuturesCompleted(), is(1));

		final FlinkException testException2 = new FlinkException("Test exception 2");
		inputFuture2.completeExceptionally(testException2);

		assertThat(completeFuture.isDone(), is(true));
		assertThat(completeFuture.getNumFuturesCompleted(), is(2));

		try {
			completeFuture.get();
			fail("Expected an exceptional completion");
		} catch (ExecutionException ee) {
			final Throwable actual = ExceptionUtils.stripExecutionException(ee);

			final Throwable[] suppressed = actual.getSuppressed();
			final FlinkException suppressedException;

			if (actual.equals(testException1)) {
				suppressedException = testException2;
			} else {
				suppressedException = testException1;
			}

			assertThat(suppressed, is(not(emptyArray())));
			assertThat(suppressed, arrayContaining(suppressedException));
		}
	}

	@Test
	public void testSupplyAsyncFailure() throws Exception {
		final String exceptionMessage = "Test exception";
		final FlinkException testException = new FlinkException(exceptionMessage);
		final CompletableFuture<Object> future = FutureUtils.supplyAsync(
			() -> {
				throw testException;
			},
			TestingUtils.defaultExecutor());

		try {
			future.get();
			fail("Expected an exception.");
		} catch (ExecutionException e) {
			assertThat(ExceptionUtils.findThrowableWithMessage(e, exceptionMessage).isPresent(), is(true));
		}
	}

	@Test
	public void testSupplyAsync() throws Exception {
		final CompletableFuture<Acknowledge> future = FutureUtils.supplyAsync(
			Acknowledge::get,
			TestingUtils.defaultExecutor());

		assertThat(future.get(), is(Acknowledge.get()));
	}

	@Test
	public void testHandleAsyncIfNotDone() {
		testFutureContinuation((CompletableFuture<?> future, Executor executor) ->
			FutureUtils.handleAsyncIfNotDone(
				future,
				executor,
				(o, t) -> null));
	}

	@Test
	public void testApplyAsyncIfNotDone() {
		testFutureContinuation((CompletableFuture<?> future, Executor executor) ->
			FutureUtils.thenApplyAsyncIfNotDone(
				future,
				executor,
				o -> null));
	}

	@Test
	public void testComposeAsyncIfNotDone() {
		testFutureContinuation((CompletableFuture<?> future, Executor executor) ->
			FutureUtils.thenComposeAsyncIfNotDone(
				future,
				executor,
				o -> null));
	}

	@Test
	public void testWhenCompleteAsyncIfNotDone() {
		testFutureContinuation((CompletableFuture<?> future, Executor executor) ->
			FutureUtils.whenCompleteAsyncIfNotDone(
			future,
			executor,
			(o, throwable) -> {
			}));
	}

	@Test
	public void testThenAcceptAsyncIfNotDone() {
		testFutureContinuation((CompletableFuture<?> future, Executor executor) ->
			FutureUtils.thenAcceptAsyncIfNotDone(
				future,
				executor,
				o -> {
				}));
	}

	private void testFutureContinuation(BiFunction<CompletableFuture<?>, Executor, CompletableFuture<?>> testFunctionGenerator) {

		CompletableFuture<?> startFuture = new CompletableFuture<>();
		final AtomicBoolean runWithExecutor = new AtomicBoolean(false);

		Executor executor = r -> {
			r.run();
			runWithExecutor.set(true);
		};

		// branch for a start future that has not completed
		CompletableFuture<?> continuationFuture = testFunctionGenerator.apply(startFuture, executor);
		Assert.assertFalse(continuationFuture.isDone());

		startFuture.complete(null);

		Assert.assertTrue(runWithExecutor.get());
		Assert.assertTrue(continuationFuture.isDone());

		// branch for a start future that was completed
		runWithExecutor.set(false);

		continuationFuture = testFunctionGenerator.apply(startFuture, executor);

		Assert.assertFalse(runWithExecutor.get());
		Assert.assertTrue(continuationFuture.isDone());
	}

	@Test
	public void testHandleUncaughtExceptionWithCompletedFuture() {
		final CompletableFuture<String> future = CompletableFuture.completedFuture("foobar");
		final TestingUncaughtExceptionHandler uncaughtExceptionHandler = new TestingUncaughtExceptionHandler();

		FutureUtils.handleUncaughtException(future, uncaughtExceptionHandler);
		assertThat(uncaughtExceptionHandler.hasBeenCalled(), is(false));
	}

	@Test
	public void testHandleUncaughtExceptionWithNormalCompletion() {
		final CompletableFuture<String> future = new CompletableFuture<>();

		final TestingUncaughtExceptionHandler uncaughtExceptionHandler = new TestingUncaughtExceptionHandler();

		FutureUtils.handleUncaughtException(future, uncaughtExceptionHandler);
		future.complete("barfoo");
		assertThat(uncaughtExceptionHandler.hasBeenCalled(), is(false));
	}

	@Test
	public void testHandleUncaughtExceptionWithExceptionallyCompletedFuture() {
		final CompletableFuture<String> future = FutureUtils.completedExceptionally(new FlinkException("foobar"));

		final TestingUncaughtExceptionHandler uncaughtExceptionHandler = new TestingUncaughtExceptionHandler();

		FutureUtils.handleUncaughtException(future, uncaughtExceptionHandler);
		assertThat(uncaughtExceptionHandler.hasBeenCalled(), is(true));
	}

	@Test
	public void testHandleUncaughtExceptionWithExceptionallyCompletion() {
		final CompletableFuture<String> future = new CompletableFuture<>();

		final TestingUncaughtExceptionHandler uncaughtExceptionHandler = new TestingUncaughtExceptionHandler();

		FutureUtils.handleUncaughtException(future, uncaughtExceptionHandler);
		assertThat(uncaughtExceptionHandler.hasBeenCalled(), is(false));
		future.completeExceptionally(new FlinkException("barfoo"));
		assertThat(uncaughtExceptionHandler.hasBeenCalled(), is(true));
	}

	private static class TestingUncaughtExceptionHandler implements Thread.UncaughtExceptionHandler {

		private Throwable exception = null;

		@Override
		public void uncaughtException(Thread t, Throwable e) {
			exception = e;
		}

		private boolean hasBeenCalled() {
			return exception != null;
		}
	}

	@Test
	public void testForwardNormal() throws Exception {
		final CompletableFuture<String> source = new CompletableFuture<>();
		final CompletableFuture<String> target = new CompletableFuture<>();

		FutureUtils.forward(source, target);

		assertThat(target.isDone(), is(source.isDone()));

		source.complete("foobar");

		assertThat(target.isDone(), is(source.isDone()));
		assertThat(target.get(), is(equalTo(source.get())));
	}

	@Test
	public void testForwardExceptionally() {
		final CompletableFuture<String> source = new CompletableFuture<>();
		final CompletableFuture<String> target = new CompletableFuture<>();

		FutureUtils.forward(source, target);

		assertThat(target.isDone(), is(source.isDone()));

		source.completeExceptionally(new FlinkException("foobar"));

		assertThat(target.isDone(), is(source.isDone()));

		Throwable targetException = getThrowable(target);
		Throwable actualException = getThrowable(source);

		assertThat(targetException, is(equalTo(actualException)));
	}

	@Test
	public void testForwardAsync() throws Exception {
		final CompletableFuture<String> source = new CompletableFuture<>();
		final CompletableFuture<String> target = new CompletableFuture<>();
		final ManuallyTriggeredScheduledExecutor executor = new ManuallyTriggeredScheduledExecutor();

		FutureUtils.forwardAsync(source, target, executor);

		source.complete("foobar");

		assertThat(target.isDone(), is(false));

		// execute the forward action
		executor.triggerAll();

		assertThat(target.get(), is(equalTo(source.get())));
	}

	@Test
	public void testGetWithoutException() {
		final CompletableFuture<Integer> completableFuture = new CompletableFuture<>();
		completableFuture.complete(1);

		assertEquals(new Integer(1), FutureUtils.getWithoutException(completableFuture));
	}

	@Test
	public void testGetWithoutExceptionWithAnException() {
		final CompletableFuture<Integer> completableFuture = new CompletableFuture<>();
		completableFuture.completeExceptionally(new RuntimeException("expected"));

		assertNull(FutureUtils.getWithoutException(completableFuture));
	}

	@Test
	public void testGetWithoutExceptionWithoutFinishing() {
		final CompletableFuture<Integer> completableFuture = new CompletableFuture<>();

		assertNull(FutureUtils.getWithoutException(completableFuture));
	}

	private static Throwable getThrowable(CompletableFuture<?> completableFuture) {
		try {
			completableFuture.join();
		} catch (CompletionException e) {
			return e.getCause();
		}

		throw new AssertionError("Future has not been completed exceptionally.");
	}
}
